<?xml version="1.0" encoding="UTF-8"?>
<testsuites name="Mocha Tests" time="0.211" tests="1" failures="1">
  <testsuite name="Root Suite" timestamp="2025-06-10T13:57:50" tests="1" file="cypress/e2e/Spec1.cy.js" time="0.211" failures="1">
    <testcase name="An uncaught error was detected outside of a test" time="0.000" classname="An uncaught error was detected outside of a test">
      <failure message="The following error originated from your test code, not from Cypress.

  &gt; Cannot access &apos;LinkedPage&apos; before initialization

When Cypress detects uncaught errors originating from your test code it will automatically fail the current test.

Cypress could not associate this error to any specific test.

We dynamically generated a new test to display this failure." type="ReferenceError"><![CDATA[ReferenceError: The following error originated from your test code, not from Cypress.

  > Cannot access 'LinkedPage' before initialization

When Cypress detects uncaught errors originating from your test code it will automatically fail the current test.

Cypress could not associate this error to any specific test.

We dynamically generated a new test to display this failure.
    at Suite.eval (webpack://cypress/./cypress/e2e/Spec1.cy.js:19:21)
    at Object.create (http://localhost:53515/__cypress/runner/cypress_runner.js:164545:19)
    at context.describe.context.context (http://localhost:53515/__cypress/runner/cypress_runner.js:164232:27)
    at createRunnable (http://localhost:53515/__cypress/runner/cypress_runner.js:148247:31)
    at <unknown> (http://localhost:53515/__cypress/runner/cypress_runner.js:148308:14)
    at eval (webpack://cypress/./cypress/e2e/Spec1.cy.js:18:0)
    at eval (http://localhost:53515/__cypress/tests?p=cypress/e2e/Spec1.cy.js:40:12)
    at eval (<anonymous>)
    at <unknown> (http://localhost:53515/__cypress/runner/cypress_runner.js:112902:23)
    at tryCatcher (http://localhost:53515/__cypress/runner/cypress_runner.js:1777:23)]]></failure>
    </testcase>
  </testsuite>
</testsuites>